<?xml version="1.0" encoding="utf-8"?>
<robot name="ur10">
    <link name="base_link">
        <collision>
            <origin xyz="0 0 0.02" rpy="0 0 0"/>
            <geometry>
                <cylinder radius="0.075" length="0.03"/>
            </geometry>
        </collision>
        <visual>
            <origin xyz="0 0 0" rpy="0 0 0"/>
            <geometry>
                <mesh filename="../meshes/ur10_base.obj" scale="1 1 1"/>
            </geometry>
        </visual>
        <inertial>
            <mass value="200.0"/>
        </inertial>
    </link>
    <link name="shoulder_link" >
        <visual>
            <origin xyz="0 0 0" rpy="0 0 0"/>
            <geometry>
                <mesh filename="../meshes/ur10_shoulder.obj" scale="1 1 1"/>
            </geometry>
        </visual>
        <collision>
            <origin xyz="0 0.0 0.13" rpy="0 0 0"/>
            <geometry>
                <cylinder radius="0.075" length="0.17"/>
            </geometry>
        </collision>
        <collision>
            <origin xyz="0 .0425 0.128" rpy="1.57079632679 0 0"/>
            <geometry>
                <cylinder radius="0.075" length="0.085"/>
            </geometry>
        </collision>
        <inertial>
            <mass value="7.1"/>
        </inertial>
    </link>
    <link name="upper_arm_link" >
        <visual>
            <origin xyz="0 0 0" rpy="0 0 0"/>
            <geometry>
                <mesh filename="../meshes/ur10_upper_arm.obj" scale="1 1 1"/>
            </geometry>
        </visual>
        <collision>
            <origin xyz="0 0 0" rpy="1.57079632679 0 0"/>
            <geometry>
                <cylinder radius="0.075" length="0.175"/>
            </geometry>
        </collision>
        <collision>
            <origin xyz="0.306 0 0" rpy="0 1.57079632679 0"/>
            <geometry>
                <cylinder radius="0.06" length="0.612"/>
            </geometry>
        </collision>
        <collision>
            <origin xyz="0.612 0 0" rpy="1.57079632679 0 0"/>
            <geometry>
                <cylinder radius="0.06" length="0.136"/>
            </geometry>
        </collision>
        <inertial>
            <mass value="12.7"/>
        </inertial>
    </link>
    <link name="forearm_link" >
        <visual>
            <origin xyz="0 0 0" rpy="0 0 0"/>
            <geometry>
                <mesh filename="../meshes/ur10_forearm.obj" scale="1 1 1"/>
            </geometry>
        </visual>
        <collision>
            <origin xyz="0 -0.00311 0" rpy="1.57079632679 0 0"/>
            <geometry>
                <cylinder radius="0.06" length="0.126"/>
            </geometry>
        </collision>
        <collision>
            <origin xyz="0.286 0 0" rpy="0 1.57079632679 0"/>
            <geometry>
                <cylinder radius="0.047" length="0.572"/>
            </geometry>
        </collision>
        <collision>
            <origin xyz="0.572 0.0028 0" rpy="1.57079632679 0 0"/>
            <geometry>
                <cylinder radius="0.047" length="0.118"/>
            </geometry>
        </collision>
        <inertial>
            <mass value="4.27"/>
        </inertial>
    </link>
    <link name="wrist_1_link" >
        <visual>
            <origin xyz="0 0 0" rpy="0 0 0"/>
            <geometry>
                <mesh filename="../meshes/ur10_wrist_1.obj" scale="1 1 1"/>
            </geometry>
        </visual>
        <collision>
            <origin xyz="0.0 -0.0275 0" rpy="1.57079632679 0 0"/>
            <geometry>
                <cylinder radius="0.047" length="0.055"/>
            </geometry>
        </collision>
        <collision>
            <origin xyz="0.0 0 -0.0028" rpy="0 0 0"/>
            <geometry>
                <cylinder radius="0.047" length="0.118"/>
            </geometry>
        </collision>
        <inertial>
            <mass value="1.0"/>
        </inertial>
    </link>
    <link name="wrist_2_link" >
        <visual>
            <origin xyz="0 0 0" rpy="0 0 0"/>
            <geometry>
                <mesh filename="../meshes/ur10_wrist_2.obj" scale="1 1 1"/>
            </geometry>
        </visual>
        <collision>
            <origin xyz="0.0 0 0.027" rpy="0 0 0"/>
            <geometry>
                <cylinder radius="0.047" length="0.054"/>
            </geometry>
        </collision>
        <collision>
            <origin xyz="0.0 0.0028 0.0" rpy="1.57079632679 0 0"/>
            <geometry>
                <cylinder radius="0.047" length="0.118"/>
            </geometry>
        </collision>
        <inertial>
            <mass value="1.0"/>
        </inertial>
    </link>
    <link name="wrist_3_link" >
        <visual>
            <origin xyz="0 0 0" rpy="0 0 0"/>
            <geometry>
                <mesh filename="../meshes/ur10_wrist_3.obj" scale="1 1 1"/>
            </geometry>
        </visual>
        <collision>
            <origin xyz="0.0 -0.015 0.0" rpy="1.57079632679 0 0"/>
            <geometry>
                <cylinder radius="0.047" length="0.03"/>
            </geometry>
        </collision>
        <inertial>
            <mass value="0.365"/>
        </inertial>
    </link>
    <joint name="shoulder_pan_joint" type="revolute">
        <origin xyz="0 0 0" rpy="0 0 0"/>
        <axis xyz="0 0 1" />
        <limit upper="6.28318" lower="-6.28318" velocity="2.0944" effort="330" />
        <parent link="base_link" />
        <child link ="shoulder_link" />
    </joint>
    <joint name="shoulder_lift_joint" type="revolute">
        <origin xyz="0 .176 0.128" rpy="0 0 0"/>
        <axis xyz="0 1 0" />
        <limit upper="6.28318" lower="-6.28318" velocity="2.0944" effort="330.0" />
        <parent link ="shoulder_link" />
        <child link="upper_arm_link" />
    </joint>
    <joint name="elbow_joint" type="revolute">
        <origin xyz="0.612 -0.128 0" rpy="0 0 0"/>
        <axis xyz="0 1 0" />
        <limit upper="6.28318" lower="-6.28318" velocity="3.14159" effort="150.0" />
        <parent link ="upper_arm_link" />
        <child link="forearm_link" />
    </joint>
    <joint name="wrist_1_joint" type="revolute">
        <origin xyz="0.572 0.116 0" rpy="0 0 0"/>
        <axis xyz="0 1 0" />
        <limit upper="6.28318" lower="-6.28318" velocity="3.14159" effort="56.0" />
        <parent link ="forearm_link" />
        <child link="wrist_1_link" />
    </joint>
    <joint name="wrist_2_joint" type="revolute">
        <origin xyz="0 0 -0.116" rpy="0 0 0"/>
        <axis xyz="0 0 -1" />
        <limit upper="6.28318" lower="-6.28318" velocity="3.14159" effort="56.0" />
        <parent link ="wrist_1_link" />
        <child link="wrist_2_link" />
    </joint>
    <joint name="wrist_3_joint" type="revolute">
        <origin xyz="0 0.092 0" rpy="0 0 0"/>
        <axis xyz="0 1 0" />
        <limit upper="6.28318" lower="-6.28318" velocity="3.14159" effort="56.0" />
        <parent link ="wrist_2_link" />
        <child link="wrist_3_link" />
    </joint>
</robot>