<robot name="UR10_CB3">
    <material name="gray">
       <color rgba="0.25 0.25 0.25 1"/>
    </material>
    <link name="base_link">
        <collision>
            <origin xyz="0 0 0.005" rpy="0 0 0"/>
            <geometry>
                <cylinder radius="0.075" length="0.01"/>
            </geometry>
        </collision>
        <visual>
            <origin xyz="0 0 0" rpy="0 0 0"/>
            <geometry>
                <mesh filename="../meshes/ur10_base.dae" scale="1.0"/>
            </geometry>
            <material name="gray"/>
        </visual>
        <inertial>
            <mass value="20.0"/>
        </inertial>
    </link>
    <link name="shoulder_link" >
        <visual>
            <origin xyz="0 0 0" rpy="0 0 0"/>
            <geometry>
                <mesh filename="../meshes/ur10_shoulder.dae" scale="1.0"/>
            </geometry>
            <material name="gray"/>
        </visual>
        <collision>
            <origin xyz="0 0.0 0.1125" rpy="0 0 0"/>
            <geometry>
                <cylinder radius="0.075" length="0.20"/>
            </geometry>
        </collision>
        <collision>
            <origin xyz="0 .05 0.128" rpy="1.57 0 0"/>
            <geometry>
                <cylinder radius="0.075" length="0.1"/>
            </geometry>
        </collision>
        <inertial>
            <mass value="7.1"/>
        </inertial>
    </link>
    <link name="elbow_link" >
        <visual>
            <origin xyz="0 0 0" rpy="0 0 0"/>
            <geometry>
                <mesh filename="../meshes/ur10_elbow.dae" scale="1.0"/>
            </geometry>
            <material name="gray"/>
        </visual>
        <collision>
            <origin xyz="0 0 0" rpy="1.57 0 0"/>
            <geometry>
                <cylinder radius="0.075" length="0.15"/>
            </geometry>
        </collision>
        <collision>
            <origin xyz="0.306 0 0" rpy="0 1.57 0"/>
            <geometry>
                <cylinder radius="0.06" length="0.612"/>
            </geometry>
        </collision>
        <collision>
            <origin xyz="0.612 0 0" rpy="1.57 0 0"/>
            <geometry>
                <cylinder radius="0.06" length="0.12"/>
            </geometry>
        </collision>
        <inertial>
            <mass value="12.7"/>
        </inertial>
    </link>
    <link name="upper_arm_link" >
        <visual>
            <origin xyz="0 0 0" rpy="0 0 0"/>
            <geometry>
                <mesh filename="../meshes/ur10_wrist_1.dae" scale="1.0"/>
            </geometry>
            <material name="gray"/>
        </visual>
        <collision>
            <origin xyz="0 0 0" rpy="1.57 0 0"/>
            <geometry>
                <cylinder radius="0.06" length="0.12"/>
            </geometry>
        </collision>
        <collision>
            <origin xyz="0.286 0 0" rpy="0 1.57 0"/>
            <geometry>
                <cylinder radius="0.05" length="0.572"/>
            </geometry>
        </collision>
        <collision>
            <origin xyz="0.572 0 0" rpy="1.57 0 0"/>
            <geometry>
                <cylinder radius="0.05" length="0.1"/>
            </geometry>
        </collision>
        <inertial>
            <mass value="4.27"/>
        </inertial>
    </link>
    <link name="wrist_1_link" >
        <visual>
            <origin xyz="0 0 0" rpy="0 0 0"/>
            <geometry>
                <mesh filename="../meshes/ur10_wrist_2.dae" scale="1.0"/>
            </geometry>
            <material name="gray"/>
        </visual>
        <collision>
            <origin xyz="0.0 -0.005 0" rpy="1.57 0 0"/>
            <geometry>
                <cylinder radius="0.05" length="0.110"/>
            </geometry>
        </collision>
        <collision>
            <origin xyz="0.0 0 -0.03" rpy="0 0 0"/>
            <geometry>
                <cylinder radius="0.05" length="0.06"/>
            </geometry>
        </collision>
        <inertial>
            <mass value="1.0"/>
        </inertial>
    </link>
    <link name="wrist_2_link" >
        <visual>
            <origin xyz="0 0 0" rpy="0 0 0"/>
            <geometry>
                <mesh filename="../meshes/ur10_wrist_3.dae" scale="1.0"/>
            </geometry>
            <material name="gray"/>
        </visual>
        <collision>
            <origin xyz="0.0 0 0.0" rpy="0 0 0"/>
            <geometry>
                <cylinder radius="0.05" length="0.10"/>
            </geometry>
        </collision>
        <collision>
            <origin xyz="0.0 0.035 0.0" rpy="1.57 0 0"/>
            <geometry>
                <cylinder radius="0.05" length="0.07"/>
            </geometry>
        </collision>
        <inertial>
            <mass value="1.0"/>
        </inertial>
    </link>
    <link name="wrist_3_link" >
        <visual>
            <origin xyz="0 0 0" rpy="0 0 0"/>
            <geometry>
                <mesh filename="../meshes/ur10_tool.dae" scale="1.0"/>
            </geometry>
            <material name="gray"/>
        </visual>
        <collision>
            <origin xyz="0.0 -0.01 0.0" rpy="1.57 0 0"/>
            <geometry>
                <cylinder radius="0.05" length="0.02"/>
            </geometry>
        </collision>
        <inertial>
            <mass value="0.365"/>
        </inertial>
    </link>
    <joint name="shoulder_pan_joint" type="revolute">
        <origin xyz="0 0 0" rpy="0 0 0"/>
        <axis xyz="0 0 1" />
        <limit upper="6.28318" lower="-6.28318" velocity="2.0944" effort="330" />
        <parent link="base_link" />
        <child link ="shoulder_link" />
    </joint>
    <joint name="shoulder_lift_joint" type="revolute">
        <origin xyz="0 .176 0.128" rpy="0 0 0"/>
        <axis xyz="0 1 0" />
        <limit upper="6.28318" lower="-6.28318" velocity="2.0944" effort="330.0" />
        <parent link ="shoulder_link" />
        <child link="elbow_link" />
    </joint>
    <joint name="elbow_joint" type="revolute">
        <origin xyz="0.612 -0.128 0" rpy="0 0 0"/>
        <axis xyz="0 1 0" />
        <limit upper="6.28318" lower="-6.28318" velocity="3.14159" effort="150.0" />
        <parent link ="elbow_link" />
        <child link="upper_arm_link" />
    </joint>
    <joint name="wrist_1_joint" type="revolute">
        <origin xyz="0.572 0.116 0" rpy="0 0 0"/>
        <axis xyz="0 1 0" />
        <limit upper="6.28318" lower="-6.28318" velocity="3.14159" effort="56.0" />
        <parent link ="upper_arm_link" />
        <child link="wrist_1_link" />
    </joint>
    <joint name="wrist_2_joint" type="revolute">
        <origin xyz="0 0 -0.116" rpy="0 0 0"/>
        <axis xyz="0 0 -1" />
        <limit upper="6.28318" lower="-6.28318" velocity="3.14159" effort="56.0" />
        <parent link ="wrist_1_link" />
        <child link="wrist_2_link" />
    </joint>
    <joint name="wrist_3_joint" type="revolute">
        <origin xyz="0 0.092 0" rpy="0 0 0"/>
        <axis xyz="0 1 0" />
        <limit upper="6.28318" lower="-6.28318" velocity="3.14159" effort="56.0" />
        <parent link ="wrist_2_link" />
        <child link="wrist_3_link" />
    </joint>
</robot>