<?xml version="1.0" encoding="utf-8"?>
<!-- =================================================================================== -->
<!-- |    This document was autogenerated by xacro from kaya.xacro                     | -->
<!-- |    EDITING THIS FILE BY HAND IS NOT RECOMMENDED                                 | -->
<!-- =================================================================================== -->
<robot name="kaya">
  <link name="base_link">
    <visual>
      <geometry>
        <mesh filename="package://meshes/base.dae"/>
      </geometry>
    </visual>
    <collision>
      <geometry>
        <mesh filename="package://meshes/base_collision.dae"/>
      </geometry>
    </collision>
  </link>
  <link name="assembly_battery">
    <visual>
      <geometry>
        <mesh filename="package://meshes/assembly_battery.dae"/>
      </geometry>
    </visual>
    <collision>
      <origin rpy="0 0 0" xyz="0.00033 -0.0127 0.00241"/>
      <geometry>
        <box size="0.770 1.140 0.486"/>
      </geometry>
    </collision>
    <inertial>
      <origin rpy="0 0 0" xyz="0.00033 -0.0127 0.00241"/>
      <mass value="0.4266108"/>
      <inertia ixx="0.0545989300164" ixy="0" ixz="0" iyy="0.0294751089864" iyz="0" izz="0.06728007825"/>
    </inertial>
  </link>
  <joint name="assembly_battery_joint" type="fixed">
    <origin xyz="0.00996 0.55389 -0.33654"/>
    <parent link="base_link"/>
    <child link="assembly_battery"/>
  </joint>
  <link name="nano_chassis_base">
    <visual>
      <geometry>
        <mesh filename="package://meshes/nano_chassis_base.dae"/>
      </geometry>
    </visual>
  </link>
  <joint name="nano_chassis_base_joint" type="fixed">
    <origin xyz="0.00825 0.77436 0.24927"/>
    <parent link="base_link"/>
    <child link="nano_chassis_base"/>
  </joint>
  <link name="nano_chassis_bridge">
    <visual>
      <geometry>
        <mesh filename="package://meshes/nano_chassis_bridge.dae"/>
      </geometry>
    </visual>
  </link>
  <joint name="nano_chassis_bridge_joint" type="fixed">
    <origin xyz="0.01140 0.71549 0.62302"/>
    <parent link="base_link"/>
    <child link="nano_chassis_bridge"/>
  </joint>
  <link name="shock_mount_0">
    <visual>
      <geometry>
        <mesh filename="package://meshes/shock_mount.dae"/>
      </geometry>
    </visual>
  </link>
  <joint name="shock_mount_0_joint" type="fixed">
    <origin xyz="-0.21377 0.75734 0.73117"/>
    <parent link="base_link"/>
    <child link="shock_mount_0"/>
  </joint>
  <link name="shock_mount_1">
    <visual>
      <geometry>
        <mesh filename="package://meshes/shock_mount.dae"/>
      </geometry>
    </visual>
  </link>
  <joint name="shock_mount_1_joint" type="fixed">
    <origin xyz=" 0.23644 0.75734 0.73117"/>
    <parent link="base_link"/>
    <child link="shock_mount_1"/>
  </joint>
  <link name="shock_mount_2">
    <visual>
      <geometry>
        <mesh filename="package://meshes/shock_mount.dae"/>
      </geometry>
    </visual>
  </link>
  <joint name="shock_mount_2_joint" type="fixed">
    <origin xyz=" 0.01141 0.54717 0.73117"/>
    <parent link="base_link"/>
    <child link="shock_mount_2"/>
  </joint>
  <link name="nano_chassis_rs_mount">
    <visual>
      <geometry>
        <mesh filename="package://meshes/nano_chassis_rs_mount.dae"/>
      </geometry>
    </visual>
  </link>
  <joint name="nano_chassis_rs_mount_joint" type="fixed">
    <origin xyz="0.01192 0.79804 0.84978"/>
    <parent link="base_link"/>
    <child link="nano_chassis_rs_mount"/>
  </joint>
  <link name="realsense">
    <visual>
      <geometry>
        <mesh filename="package://meshes/realsense.dae"/>
      </geometry>
    </visual>
  </link>
  <joint name="realsense_joint" type="fixed">
    <origin xyz="0.01053 0.90384 0.90843"/>
    <parent link="base_link"/>
    <child link="realsense"/>
  </joint>
  <link name="pusher">
    <visual>
      <geometry>
        <mesh filename="package://meshes/pusher.dae"/>
      </geometry>
    </visual>
    <collision>
      <origin rpy="0 0 0" xyz="       0 -0.00983 -0.47219"/>
      <geometry>
        <box size="0.290 0.090 0.952"/>
      </geometry>
    </collision>
    <collision>
      <origin rpy="0 0 -0.41888" xyz="-0.49078  0.17466 -0.74854"/>
      <geometry>
        <box size="0.904 0.056 0.394"/>
      </geometry>
    </collision>
    <collision>
      <origin rpy="0 0  0.41888" xyz=" 0.49078  0.17466 -0.74854"/>
      <geometry>
        <box size="0.904 0.056 0.394"/>
      </geometry>
    </collision>
    <collision>
      <origin rpy="0 0 -1.05770" xyz="-0.95612  0.44530 -0.81565"/>
      <geometry>
        <box size="0.198 0.056 0.258"/>
      </geometry>
    </collision>
    <collision>
      <origin rpy="0 0  1.05770" xyz=" 0.95612  0.44530 -0.81565"/>
      <geometry>
        <box size="0.198 0.056 0.258"/>
      </geometry>
    </collision>
  </link>
  <joint name="pusher_joint" type="fixed">
    <origin xyz="0.0 1.24025 0.15933"/>
    <parent link="base_link"/>
    <child link="pusher"/>
  </joint>
  <link name="mx12w_0">
    <visual>
      <geometry>
        <mesh filename="package://meshes/mx12w.dae"/>
      </geometry>
    </visual>
    <collision>
      <origin rpy="0 0 0" xyz="0 0 0"/>
      <geometry>
        <box size="0.328 0.380 0.502"/>
      </geometry>
    </collision>
    <inertial>
      <origin rpy="0 0 0" xyz="0 0 0"/>
      <mass value="0.06256928"/>
      <inertia ixx="0.00206689273909" ixy="0" ixz="0" iyy="0.00187493018805" iyz="0" izz="0.00131387145429"/>
    </inertial>
  </link>
  <joint name="mx12w_0_joint" type="fixed">
    <origin rpy="0 0 0" xyz=" 0.00105 -0.25453 -0.32597"/>
    <parent link="base_link"/>
    <child link="mx12w_0"/>
  </joint>
  <link name="axle_0">
    <visual>
      <geometry>
        <mesh filename="package://meshes/axle.dae"/>
      </geometry>
    </visual>
    <collision>
      <origin rpy="1.57079632679 0 0" xyz="0.0 -0.18622 0.0"/>
      <geometry>
        <cylinder length="0.448" radius="0.155"/>
      </geometry>
    </collision>
    <inertial>
      <origin rpy="1.57079632679 0 0" xyz="0.0 -0.18622 0.0"/>
      <mass value="0.0338135900491"/>
      <inertia ixx="0.000768636440001" ixy="0" ixz="0" iyy="0.000768636440001" iyz="0" izz="0.000406185750465"/>
    </inertial>
  </link>
  <joint name="axle_0_joint" type="continuous">
    <origin xyz="-0.00105 -0.22823 -0.12904"/>
    <axis xyz="0 -1 0"/>
    <parent link="mx12w_0"/>
    <child link="axle_0"/>
  </joint>
  <link name="wheel_0">
    <visual>
      <geometry>
        <mesh filename="package://meshes/wheel_and_rollers.dae"/>
      </geometry>
    </visual>
    <collision>
      <origin rpy="1.57079632679 0 0" xyz="0 0 0"/>
      <geometry>
        <cylinder length="0.292" radius="0.34"/>
      </geometry>
    </collision>
    <inertial>
      <origin rpy="1.57079632679 0 0" xyz="0 0 0"/>
      <mass value="0.131073930817"/>
      <inertia ixx="0.00561341585248" ixy="0" ixz="0" iyy="0.00561341585248" iyz="0" izz="0.00936418376542"/>
    </inertial>
  </link>
  <joint name="wheel_0_joint" type="fixed">
    <origin xyz="-0.00023 -0.19556 -0.00006"/>
    <axis xyz="0 -1 0"/>
    <parent link="axle_0"/>
    <child link="wheel_0"/>
  </joint>
  <link name="roller_0_0_0">
    <visual>
      <geometry>
        <box size="0.001 0.001 0.001"/>
      </geometry>
    </visual>
    <collision>
      <origin rpy="0 0 0" xyz="0 0 0"/>
      <geometry>
        <sphere radius="0.2"/>
      </geometry>
    </collision>
    <inertial>
      <origin rpy="0 1.57079632679 0" xyz="0 0 0"/>
      <mass value="0.00644011414341"/>
      <inertia ixx="4.31122707807e-05" ixy="0" ixz="0" iyy="4.31122707807e-05" iyz="0" izz="2.84524242856e-05"/>
    </inertial>
  </link>
  <joint name="roller_0_0_0_joint" type="continuous">
    <origin rpy="0 -0.0 0" xyz="0.0        0.09521        -0.21319"/>
    <parent link="wheel_0"/>
    <child link="roller_0_0_0"/>
  </joint>
  <link name="roller_0_0_1">
    <visual>
      <geometry>
        <box size="0.001 0.001 0.001"/>
      </geometry>
    </visual>
    <collision>
      <origin rpy="0 0 0" xyz="0 0 0"/>
      <geometry>
        <sphere radius="0.2"/>
      </geometry>
    </collision>
    <inertial>
      <origin rpy="0 1.57079632679 0" xyz="0 0 0"/>
      <mass value="0.00644011414341"/>
      <inertia ixx="4.31122707807e-05" ixy="0" ixz="0" iyy="4.31122707807e-05" iyz="0" izz="2.84524242856e-05"/>
    </inertial>
  </link>
  <joint name="roller_0_0_1_joint" type="continuous">
    <origin rpy="0 -1.25663706144 0" xyz="0.202755738709        0.09521        -0.0658793330308"/>
    <parent link="wheel_0"/>
    <child link="roller_0_0_1"/>
  </joint>
  <link name="roller_0_0_2">
    <visual>
      <geometry>
        <box size="0.001 0.001 0.001"/>
      </geometry>
    </visual>
    <collision>
      <origin rpy="0 0 0" xyz="0 0 0"/>
      <geometry>
        <sphere radius="0.2"/>
      </geometry>
    </collision>
    <inertial>
      <origin rpy="0 1.57079632679 0" xyz="0 0 0"/>
      <mass value="0.00644011414341"/>
      <inertia ixx="4.31122707807e-05" ixy="0" ixz="0" iyy="4.31122707807e-05" iyz="0" izz="2.84524242856e-05"/>
    </inertial>
  </link>
  <joint name="roller_0_0_2_joint" type="continuous">
    <origin rpy="0 -2.51327412287 0" xyz="0.125309937936        0.09521        0.172474333031"/>
    <parent link="wheel_0"/>
    <child link="roller_0_0_2"/>
  </joint>
  <link name="roller_0_0_3">
    <visual>
      <geometry>
        <box size="0.001 0.001 0.001"/>
      </geometry>
    </visual>
    <collision>
      <origin rpy="0 0 0" xyz="0 0 0"/>
      <geometry>
        <sphere radius="0.2"/>
      </geometry>
    </collision>
    <inertial>
      <origin rpy="0 1.57079632679 0" xyz="0 0 0"/>
      <mass value="0.00644011414341"/>
      <inertia ixx="4.31122707807e-05" ixy="0" ixz="0" iyy="4.31122707807e-05" iyz="0" izz="2.84524242856e-05"/>
    </inertial>
  </link>
  <joint name="roller_0_0_3_joint" type="continuous">
    <origin rpy="0 -3.76991118431 0" xyz="-0.125309937936        0.09521        0.172474333031"/>
    <parent link="wheel_0"/>
    <child link="roller_0_0_3"/>
  </joint>
  <link name="roller_0_0_4">
    <visual>
      <geometry>
        <box size="0.001 0.001 0.001"/>
      </geometry>
    </visual>
    <collision>
      <origin rpy="0 0 0" xyz="0 0 0"/>
      <geometry>
        <sphere radius="0.2"/>
      </geometry>
    </collision>
    <inertial>
      <origin rpy="0 1.57079632679 0" xyz="0 0 0"/>
      <mass value="0.00644011414341"/>
      <inertia ixx="4.31122707807e-05" ixy="0" ixz="0" iyy="4.31122707807e-05" iyz="0" izz="2.84524242856e-05"/>
    </inertial>
  </link>
  <joint name="roller_0_0_4_joint" type="continuous">
    <origin rpy="0 -5.02654824574 0" xyz="-0.202755738709        0.09521        -0.0658793330308"/>
    <parent link="wheel_0"/>
    <child link="roller_0_0_4"/>
  </joint>
  <link name="roller_0_1_0">
    <visual>
      <geometry>
        <box size="0.001 0.001 0.001"/>
      </geometry>
    </visual>
    <collision>
      <origin rpy="0 0 0" xyz="0 0 0"/>
      <geometry>
        <sphere radius="0.2"/>
      </geometry>
    </collision>
    <inertial>
      <origin rpy="0 1.57079632679 0" xyz="0 0 0"/>
      <mass value="0.00644011414341"/>
      <inertia ixx="4.31122707807e-05" ixy="0" ixz="0" iyy="4.31122707807e-05" iyz="0" izz="2.84524242856e-05"/>
    </inertial>
  </link>
  <joint name="roller_0_1_0_joint" type="continuous">
    <origin rpy="0 -0.628318530718 0" xyz="0.125309937936        -0.09521        -0.172474333031"/>
    <parent link="wheel_0"/>
    <child link="roller_0_1_0"/>
  </joint>
  <link name="roller_0_1_1">
    <visual>
      <geometry>
        <box size="0.001 0.001 0.001"/>
      </geometry>
    </visual>
    <collision>
      <origin rpy="0 0 0" xyz="0 0 0"/>
      <geometry>
        <sphere radius="0.2"/>
      </geometry>
    </collision>
    <inertial>
      <origin rpy="0 1.57079632679 0" xyz="0 0 0"/>
      <mass value="0.00644011414341"/>
      <inertia ixx="4.31122707807e-05" ixy="0" ixz="0" iyy="4.31122707807e-05" iyz="0" izz="2.84524242856e-05"/>
    </inertial>
  </link>
  <joint name="roller_0_1_1_joint" type="continuous">
    <origin rpy="0 -1.88495559215 0" xyz="0.202755738709        -0.09521        0.0658793330308"/>
    <parent link="wheel_0"/>
    <child link="roller_0_1_1"/>
  </joint>
  <link name="roller_0_1_2">
    <visual>
      <geometry>
        <box size="0.001 0.001 0.001"/>
      </geometry>
    </visual>
    <collision>
      <origin rpy="0 0 0" xyz="0 0 0"/>
      <geometry>
        <sphere radius="0.2"/>
      </geometry>
    </collision>
    <inertial>
      <origin rpy="0 1.57079632679 0" xyz="0 0 0"/>
      <mass value="0.00644011414341"/>
      <inertia ixx="4.31122707807e-05" ixy="0" ixz="0" iyy="4.31122707807e-05" iyz="0" izz="2.84524242856e-05"/>
    </inertial>
  </link>
  <joint name="roller_0_1_2_joint" type="continuous">
    <origin rpy="0 -3.14159265359 0" xyz="2.6108245111e-17        -0.09521        0.21319"/>
    <parent link="wheel_0"/>
    <child link="roller_0_1_2"/>
  </joint>
  <link name="roller_0_1_3">
    <visual>
      <geometry>
        <box size="0.001 0.001 0.001"/>
      </geometry>
    </visual>
    <collision>
      <origin rpy="0 0 0" xyz="0 0 0"/>
      <geometry>
        <sphere radius="0.2"/>
      </geometry>
    </collision>
    <inertial>
      <origin rpy="0 1.57079632679 0" xyz="0 0 0"/>
      <mass value="0.00644011414341"/>
      <inertia ixx="4.31122707807e-05" ixy="0" ixz="0" iyy="4.31122707807e-05" iyz="0" izz="2.84524242856e-05"/>
    </inertial>
  </link>
  <joint name="roller_0_1_3_joint" type="continuous">
    <origin rpy="0 -4.39822971503 0" xyz="-0.202755738709        -0.09521        0.0658793330308"/>
    <parent link="wheel_0"/>
    <child link="roller_0_1_3"/>
  </joint>
  <link name="roller_0_1_4">
    <visual>
      <geometry>
        <box size="0.001 0.001 0.001"/>
      </geometry>
    </visual>
    <collision>
      <origin rpy="0 0 0" xyz="0 0 0"/>
      <geometry>
        <sphere radius="0.2"/>
      </geometry>
    </collision>
    <inertial>
      <origin rpy="0 1.57079632679 0" xyz="0 0 0"/>
      <mass value="0.00644011414341"/>
      <inertia ixx="4.31122707807e-05" ixy="0" ixz="0" iyy="4.31122707807e-05" iyz="0" izz="2.84524242856e-05"/>
    </inertial>
  </link>
  <joint name="roller_0_1_4_joint" type="continuous">
    <origin rpy="0 -5.65486677646 0" xyz="-0.125309937936        -0.09521        -0.172474333031"/>
    <parent link="wheel_0"/>
    <child link="roller_0_1_4"/>
  </joint>
  <link name="mx12w_1">
    <visual>
      <geometry>
        <mesh filename="package://meshes/mx12w.dae"/>
      </geometry>
    </visual>
    <collision>
      <origin rpy="0 0 0" xyz="0 0 0"/>
      <geometry>
        <box size="0.328 0.380 0.502"/>
      </geometry>
    </collision>
    <inertial>
      <origin rpy="0 0 0" xyz="0 0 0"/>
      <mass value="0.06256928"/>
      <inertia ixx="0.00206689273909" ixy="0" ixz="0" iyy="0.00187493018805" iyz="0" izz="0.00131387145429"/>
    </inertial>
  </link>
  <joint name="mx12w_1_joint" type="fixed">
    <origin rpy="0 0 2.0944" xyz=" 0.65344  0.87794 -0.32597"/>
    <parent link="base_link"/>
    <child link="mx12w_1"/>
  </joint>
  <link name="axle_1">
    <visual>
      <geometry>
        <mesh filename="package://meshes/axle.dae"/>
      </geometry>
    </visual>
    <collision>
      <origin rpy="1.57079632679 0 0" xyz="0.0 -0.18622 0.0"/>
      <geometry>
        <cylinder length="0.448" radius="0.155"/>
      </geometry>
    </collision>
    <inertial>
      <origin rpy="1.57079632679 0 0" xyz="0.0 -0.18622 0.0"/>
      <mass value="0.0338135900491"/>
      <inertia ixx="0.000768636440001" ixy="0" ixz="0" iyy="0.000768636440001" iyz="0" izz="0.000406185750465"/>
    </inertial>
  </link>
  <joint name="axle_1_joint" type="continuous">
    <origin xyz="-0.00105 -0.22823 -0.12904"/>
    <axis xyz="0 -1 0"/>
    <parent link="mx12w_1"/>
    <child link="axle_1"/>
  </joint>
  <link name="wheel_1">
    <visual>
      <geometry>
        <mesh filename="package://meshes/wheel_and_rollers.dae"/>
      </geometry>
    </visual>
    <collision>
      <origin rpy="1.57079632679 0 0" xyz="0 0 0"/>
      <geometry>
        <cylinder length="0.292" radius="0.34"/>
      </geometry>
    </collision>
    <inertial>
      <origin rpy="1.57079632679 0 0" xyz="0 0 0"/>
      <mass value="0.131073930817"/>
      <inertia ixx="0.00561341585248" ixy="0" ixz="0" iyy="0.00561341585248" iyz="0" izz="0.00936418376542"/>
    </inertial>
  </link>
  <joint name="wheel_1_joint" type="fixed">
    <origin xyz="-0.00023 -0.19556 -0.00006"/>
    <axis xyz="0 -1 0"/>
    <parent link="axle_1"/>
    <child link="wheel_1"/>
  </joint>
  <link name="roller_1_0_0">
    <visual>
      <geometry>
        <box size="0.001 0.001 0.001"/>
      </geometry>
    </visual>
    <collision>
      <origin rpy="0 0 0" xyz="0 0 0"/>
      <geometry>
        <sphere radius="0.2"/>
      </geometry>
    </collision>
    <inertial>
      <origin rpy="0 1.57079632679 0" xyz="0 0 0"/>
      <mass value="0.00644011414341"/>
      <inertia ixx="4.31122707807e-05" ixy="0" ixz="0" iyy="4.31122707807e-05" iyz="0" izz="2.84524242856e-05"/>
    </inertial>
  </link>
  <joint name="roller_1_0_0_joint" type="continuous">
    <origin rpy="0 -0.0 0" xyz="0.0        0.09521        -0.21319"/>
    <parent link="wheel_1"/>
    <child link="roller_1_0_0"/>
  </joint>
  <link name="roller_1_0_1">
    <visual>
      <geometry>
        <box size="0.001 0.001 0.001"/>
      </geometry>
    </visual>
    <collision>
      <origin rpy="0 0 0" xyz="0 0 0"/>
      <geometry>
        <sphere radius="0.2"/>
      </geometry>
    </collision>
    <inertial>
      <origin rpy="0 1.57079632679 0" xyz="0 0 0"/>
      <mass value="0.00644011414341"/>
      <inertia ixx="4.31122707807e-05" ixy="0" ixz="0" iyy="4.31122707807e-05" iyz="0" izz="2.84524242856e-05"/>
    </inertial>
  </link>
  <joint name="roller_1_0_1_joint" type="continuous">
    <origin rpy="0 -1.25663706144 0" xyz="0.202755738709        0.09521        -0.0658793330308"/>
    <parent link="wheel_1"/>
    <child link="roller_1_0_1"/>
  </joint>
  <link name="roller_1_0_2">
    <visual>
      <geometry>
        <box size="0.001 0.001 0.001"/>
      </geometry>
    </visual>
    <collision>
      <origin rpy="0 0 0" xyz="0 0 0"/>
      <geometry>
        <sphere radius="0.2"/>
      </geometry>
    </collision>
    <inertial>
      <origin rpy="0 1.57079632679 0" xyz="0 0 0"/>
      <mass value="0.00644011414341"/>
      <inertia ixx="4.31122707807e-05" ixy="0" ixz="0" iyy="4.31122707807e-05" iyz="0" izz="2.84524242856e-05"/>
    </inertial>
  </link>
  <joint name="roller_1_0_2_joint" type="continuous">
    <origin rpy="0 -2.51327412287 0" xyz="0.125309937936        0.09521        0.172474333031"/>
    <parent link="wheel_1"/>
    <child link="roller_1_0_2"/>
  </joint>
  <link name="roller_1_0_3">
    <visual>
      <geometry>
        <box size="0.001 0.001 0.001"/>
      </geometry>
    </visual>
    <collision>
      <origin rpy="0 0 0" xyz="0 0 0"/>
      <geometry>
        <sphere radius="0.2"/>
      </geometry>
    </collision>
    <inertial>
      <origin rpy="0 1.57079632679 0" xyz="0 0 0"/>
      <mass value="0.00644011414341"/>
      <inertia ixx="4.31122707807e-05" ixy="0" ixz="0" iyy="4.31122707807e-05" iyz="0" izz="2.84524242856e-05"/>
    </inertial>
  </link>
  <joint name="roller_1_0_3_joint" type="continuous">
    <origin rpy="0 -3.76991118431 0" xyz="-0.125309937936        0.09521        0.172474333031"/>
    <parent link="wheel_1"/>
    <child link="roller_1_0_3"/>
  </joint>
  <link name="roller_1_0_4">
    <visual>
      <geometry>
        <box size="0.001 0.001 0.001"/>
      </geometry>
    </visual>
    <collision>
      <origin rpy="0 0 0" xyz="0 0 0"/>
      <geometry>
        <sphere radius="0.2"/>
      </geometry>
    </collision>
    <inertial>
      <origin rpy="0 1.57079632679 0" xyz="0 0 0"/>
      <mass value="0.00644011414341"/>
      <inertia ixx="4.31122707807e-05" ixy="0" ixz="0" iyy="4.31122707807e-05" iyz="0" izz="2.84524242856e-05"/>
    </inertial>
  </link>
  <joint name="roller_1_0_4_joint" type="continuous">
    <origin rpy="0 -5.02654824574 0" xyz="-0.202755738709        0.09521        -0.0658793330308"/>
    <parent link="wheel_1"/>
    <child link="roller_1_0_4"/>
  </joint>
  <link name="roller_1_1_0">
    <visual>
      <geometry>
        <box size="0.001 0.001 0.001"/>
      </geometry>
    </visual>
    <collision>
      <origin rpy="0 0 0" xyz="0 0 0"/>
      <geometry>
        <sphere radius="0.2"/>
      </geometry>
    </collision>
    <inertial>
      <origin rpy="0 1.57079632679 0" xyz="0 0 0"/>
      <mass value="0.00644011414341"/>
      <inertia ixx="4.31122707807e-05" ixy="0" ixz="0" iyy="4.31122707807e-05" iyz="0" izz="2.84524242856e-05"/>
    </inertial>
  </link>
  <joint name="roller_1_1_0_joint" type="continuous">
    <origin rpy="0 -0.628318530718 0" xyz="0.125309937936        -0.09521        -0.172474333031"/>
    <parent link="wheel_1"/>
    <child link="roller_1_1_0"/>
  </joint>
  <link name="roller_1_1_1">
    <visual>
      <geometry>
        <box size="0.001 0.001 0.001"/>
      </geometry>
    </visual>
    <collision>
      <origin rpy="0 0 0" xyz="0 0 0"/>
      <geometry>
        <sphere radius="0.2"/>
      </geometry>
    </collision>
    <inertial>
      <origin rpy="0 1.57079632679 0" xyz="0 0 0"/>
      <mass value="0.00644011414341"/>
      <inertia ixx="4.31122707807e-05" ixy="0" ixz="0" iyy="4.31122707807e-05" iyz="0" izz="2.84524242856e-05"/>
    </inertial>
  </link>
  <joint name="roller_1_1_1_joint" type="continuous">
    <origin rpy="0 -1.88495559215 0" xyz="0.202755738709        -0.09521        0.0658793330308"/>
    <parent link="wheel_1"/>
    <child link="roller_1_1_1"/>
  </joint>
  <link name="roller_1_1_2">
    <visual>
      <geometry>
        <box size="0.001 0.001 0.001"/>
      </geometry>
    </visual>
    <collision>
      <origin rpy="0 0 0" xyz="0 0 0"/>
      <geometry>
        <sphere radius="0.2"/>
      </geometry>
    </collision>
    <inertial>
      <origin rpy="0 1.57079632679 0" xyz="0 0 0"/>
      <mass value="0.00644011414341"/>
      <inertia ixx="4.31122707807e-05" ixy="0" ixz="0" iyy="4.31122707807e-05" iyz="0" izz="2.84524242856e-05"/>
    </inertial>
  </link>
  <joint name="roller_1_1_2_joint" type="continuous">
    <origin rpy="0 -3.14159265359 0" xyz="2.6108245111e-17        -0.09521        0.21319"/>
    <parent link="wheel_1"/>
    <child link="roller_1_1_2"/>
  </joint>
  <link name="roller_1_1_3">
    <visual>
      <geometry>
        <box size="0.001 0.001 0.001"/>
      </geometry>
    </visual>
    <collision>
      <origin rpy="0 0 0" xyz="0 0 0"/>
      <geometry>
        <sphere radius="0.2"/>
      </geometry>
    </collision>
    <inertial>
      <origin rpy="0 1.57079632679 0" xyz="0 0 0"/>
      <mass value="0.00644011414341"/>
      <inertia ixx="4.31122707807e-05" ixy="0" ixz="0" iyy="4.31122707807e-05" iyz="0" izz="2.84524242856e-05"/>
    </inertial>
  </link>
  <joint name="roller_1_1_3_joint" type="continuous">
    <origin rpy="0 -4.39822971503 0" xyz="-0.202755738709        -0.09521        0.0658793330308"/>
    <parent link="wheel_1"/>
    <child link="roller_1_1_3"/>
  </joint>
  <link name="roller_1_1_4">
    <visual>
      <geometry>
        <box size="0.001 0.001 0.001"/>
      </geometry>
    </visual>
    <collision>
      <origin rpy="0 0 0" xyz="0 0 0"/>
      <geometry>
        <sphere radius="0.2"/>
      </geometry>
    </collision>
    <inertial>
      <origin rpy="0 1.57079632679 0" xyz="0 0 0"/>
      <mass value="0.00644011414341"/>
      <inertia ixx="4.31122707807e-05" ixy="0" ixz="0" iyy="4.31122707807e-05" iyz="0" izz="2.84524242856e-05"/>
    </inertial>
  </link>
  <joint name="roller_1_1_4_joint" type="continuous">
    <origin rpy="0 -5.65486677646 0" xyz="-0.125309937936        -0.09521        -0.172474333031"/>
    <parent link="wheel_1"/>
    <child link="roller_1_1_4"/>
  </joint>
  <link name="mx12w_2">
    <visual>
      <geometry>
        <mesh filename="package://meshes/mx12w.dae"/>
      </geometry>
    </visual>
    <collision>
      <origin rpy="0 0 0" xyz="0 0 0"/>
      <geometry>
        <box size="0.328 0.380 0.502"/>
      </geometry>
    </collision>
    <inertial>
      <origin rpy="0 0 0" xyz="0 0 0"/>
      <mass value="0.06256928"/>
      <inertia ixx="0.00206689273909" ixy="0" ixz="0" iyy="0.00187493018805" iyz="0" izz="0.00131387145429"/>
    </inertial>
  </link>
  <joint name="mx12w_2_joint" type="fixed">
    <origin rpy="0 0 4.1888" xyz="-0.65344  0.87794 -0.32597"/>
    <parent link="base_link"/>
    <child link="mx12w_2"/>
  </joint>
  <link name="axle_2">
    <visual>
      <geometry>
        <mesh filename="package://meshes/axle.dae"/>
      </geometry>
    </visual>
    <collision>
      <origin rpy="1.57079632679 0 0" xyz="0.0 -0.18622 0.0"/>
      <geometry>
        <cylinder length="0.448" radius="0.155"/>
      </geometry>
    </collision>
    <inertial>
      <origin rpy="1.57079632679 0 0" xyz="0.0 -0.18622 0.0"/>
      <mass value="0.0338135900491"/>
      <inertia ixx="0.000768636440001" ixy="0" ixz="0" iyy="0.000768636440001" iyz="0" izz="0.000406185750465"/>
    </inertial>
  </link>
  <joint name="axle_2_joint" type="continuous">
    <origin xyz="-0.00105 -0.22823 -0.12904"/>
    <axis xyz="0 -1 0"/>
    <parent link="mx12w_2"/>
    <child link="axle_2"/>
  </joint>
  <link name="wheel_2">
    <visual>
      <geometry>
        <mesh filename="package://meshes/wheel_and_rollers.dae"/>
      </geometry>
    </visual>
    <collision>
      <origin rpy="1.57079632679 0 0" xyz="0 0 0"/>
      <geometry>
        <cylinder length="0.292" radius="0.34"/>
      </geometry>
    </collision>
    <inertial>
      <origin rpy="1.57079632679 0 0" xyz="0 0 0"/>
      <mass value="0.131073930817"/>
      <inertia ixx="0.00561341585248" ixy="0" ixz="0" iyy="0.00561341585248" iyz="0" izz="0.00936418376542"/>
    </inertial>
  </link>
  <joint name="wheel_2_joint" type="fixed">
    <origin xyz="-0.00023 -0.19556 -0.00006"/>
    <axis xyz="0 -1 0"/>
    <parent link="axle_2"/>
    <child link="wheel_2"/>
  </joint>
  <link name="roller_2_0_0">
    <visual>
      <geometry>
        <box size="0.001 0.001 0.001"/>
      </geometry>
    </visual>
    <collision>
      <origin rpy="0 0 0" xyz="0 0 0"/>
      <geometry>
        <sphere radius="0.2"/>
      </geometry>
    </collision>
    <inertial>
      <origin rpy="0 1.57079632679 0" xyz="0 0 0"/>
      <mass value="0.00644011414341"/>
      <inertia ixx="4.31122707807e-05" ixy="0" ixz="0" iyy="4.31122707807e-05" iyz="0" izz="2.84524242856e-05"/>
    </inertial>
  </link>
  <joint name="roller_2_0_0_joint" type="continuous">
    <origin rpy="0 -0.0 0" xyz="0.0        0.09521        -0.21319"/>
    <parent link="wheel_2"/>
    <child link="roller_2_0_0"/>
  </joint>
  <link name="roller_2_0_1">
    <visual>
      <geometry>
        <box size="0.001 0.001 0.001"/>
      </geometry>
    </visual>
    <collision>
      <origin rpy="0 0 0" xyz="0 0 0"/>
      <geometry>
        <sphere radius="0.2"/>
      </geometry>
    </collision>
    <inertial>
      <origin rpy="0 1.57079632679 0" xyz="0 0 0"/>
      <mass value="0.00644011414341"/>
      <inertia ixx="4.31122707807e-05" ixy="0" ixz="0" iyy="4.31122707807e-05" iyz="0" izz="2.84524242856e-05"/>
    </inertial>
  </link>
  <joint name="roller_2_0_1_joint" type="continuous">
    <origin rpy="0 -1.25663706144 0" xyz="0.202755738709        0.09521        -0.0658793330308"/>
    <parent link="wheel_2"/>
    <child link="roller_2_0_1"/>
  </joint>
  <link name="roller_2_0_2">
    <visual>
      <geometry>
        <box size="0.001 0.001 0.001"/>
      </geometry>
    </visual>
    <collision>
      <origin rpy="0 0 0" xyz="0 0 0"/>
      <geometry>
        <sphere radius="0.2"/>
      </geometry>
    </collision>
    <inertial>
      <origin rpy="0 1.57079632679 0" xyz="0 0 0"/>
      <mass value="0.00644011414341"/>
      <inertia ixx="4.31122707807e-05" ixy="0" ixz="0" iyy="4.31122707807e-05" iyz="0" izz="2.84524242856e-05"/>
    </inertial>
  </link>
  <joint name="roller_2_0_2_joint" type="continuous">
    <origin rpy="0 -2.51327412287 0" xyz="0.125309937936        0.09521        0.172474333031"/>
    <parent link="wheel_2"/>
    <child link="roller_2_0_2"/>
  </joint>
  <link name="roller_2_0_3">
    <visual>
      <geometry>
        <box size="0.001 0.001 0.001"/>
      </geometry>
    </visual>
    <collision>
      <origin rpy="0 0 0" xyz="0 0 0"/>
      <geometry>
        <sphere radius="0.2"/>
      </geometry>
    </collision>
    <inertial>
      <origin rpy="0 1.57079632679 0" xyz="0 0 0"/>
      <mass value="0.00644011414341"/>
      <inertia ixx="4.31122707807e-05" ixy="0" ixz="0" iyy="4.31122707807e-05" iyz="0" izz="2.84524242856e-05"/>
    </inertial>
  </link>
  <joint name="roller_2_0_3_joint" type="continuous">
    <origin rpy="0 -3.76991118431 0" xyz="-0.125309937936        0.09521        0.172474333031"/>
    <parent link="wheel_2"/>
    <child link="roller_2_0_3"/>
  </joint>
  <link name="roller_2_0_4">
    <visual>
      <geometry>
        <box size="0.001 0.001 0.001"/>
      </geometry>
    </visual>
    <collision>
      <origin rpy="0 0 0" xyz="0 0 0"/>
      <geometry>
        <sphere radius="0.2"/>
      </geometry>
    </collision>
    <inertial>
      <origin rpy="0 1.57079632679 0" xyz="0 0 0"/>
      <mass value="0.00644011414341"/>
      <inertia ixx="4.31122707807e-05" ixy="0" ixz="0" iyy="4.31122707807e-05" iyz="0" izz="2.84524242856e-05"/>
    </inertial>
  </link>
  <joint name="roller_2_0_4_joint" type="continuous">
    <origin rpy="0 -5.02654824574 0" xyz="-0.202755738709        0.09521        -0.0658793330308"/>
    <parent link="wheel_2"/>
    <child link="roller_2_0_4"/>
  </joint>
  <link name="roller_2_1_0">
    <visual>
      <geometry>
        <box size="0.001 0.001 0.001"/>
      </geometry>
    </visual>
    <collision>
      <origin rpy="0 0 0" xyz="0 0 0"/>
      <geometry>
        <sphere radius="0.2"/>
      </geometry>
    </collision>
    <inertial>
      <origin rpy="0 1.57079632679 0" xyz="0 0 0"/>
      <mass value="0.00644011414341"/>
      <inertia ixx="4.31122707807e-05" ixy="0" ixz="0" iyy="4.31122707807e-05" iyz="0" izz="2.84524242856e-05"/>
    </inertial>
  </link>
  <joint name="roller_2_1_0_joint" type="continuous">
    <origin rpy="0 -0.628318530718 0" xyz="0.125309937936        -0.09521        -0.172474333031"/>
    <parent link="wheel_2"/>
    <child link="roller_2_1_0"/>
  </joint>
  <link name="roller_2_1_1">
    <visual>
      <geometry>
        <box size="0.001 0.001 0.001"/>
      </geometry>
    </visual>
    <collision>
      <origin rpy="0 0 0" xyz="0 0 0"/>
      <geometry>
        <sphere radius="0.2"/>
      </geometry>
    </collision>
    <inertial>
      <origin rpy="0 1.57079632679 0" xyz="0 0 0"/>
      <mass value="0.00644011414341"/>
      <inertia ixx="4.31122707807e-05" ixy="0" ixz="0" iyy="4.31122707807e-05" iyz="0" izz="2.84524242856e-05"/>
    </inertial>
  </link>
  <joint name="roller_2_1_1_joint" type="continuous">
    <origin rpy="0 -1.88495559215 0" xyz="0.202755738709        -0.09521        0.0658793330308"/>
    <parent link="wheel_2"/>
    <child link="roller_2_1_1"/>
  </joint>
  <link name="roller_2_1_2">
    <visual>
      <geometry>
        <box size="0.001 0.001 0.001"/>
      </geometry>
    </visual>
    <collision>
      <origin rpy="0 0 0" xyz="0 0 0"/>
      <geometry>
        <sphere radius="0.2"/>
      </geometry>
    </collision>
    <inertial>
      <origin rpy="0 1.57079632679 0" xyz="0 0 0"/>
      <mass value="0.00644011414341"/>
      <inertia ixx="4.31122707807e-05" ixy="0" ixz="0" iyy="4.31122707807e-05" iyz="0" izz="2.84524242856e-05"/>
    </inertial>
  </link>
  <joint name="roller_2_1_2_joint" type="continuous">
    <origin rpy="0 -3.14159265359 0" xyz="2.6108245111e-17        -0.09521        0.21319"/>
    <parent link="wheel_2"/>
    <child link="roller_2_1_2"/>
  </joint>
  <link name="roller_2_1_3">
    <visual>
      <geometry>
        <box size="0.001 0.001 0.001"/>
      </geometry>
    </visual>
    <collision>
      <origin rpy="0 0 0" xyz="0 0 0"/>
      <geometry>
        <sphere radius="0.2"/>
      </geometry>
    </collision>
    <inertial>
      <origin rpy="0 1.57079632679 0" xyz="0 0 0"/>
      <mass value="0.00644011414341"/>
      <inertia ixx="4.31122707807e-05" ixy="0" ixz="0" iyy="4.31122707807e-05" iyz="0" izz="2.84524242856e-05"/>
    </inertial>
  </link>
  <joint name="roller_2_1_3_joint" type="continuous">
    <origin rpy="0 -4.39822971503 0" xyz="-0.202755738709        -0.09521        0.0658793330308"/>
    <parent link="wheel_2"/>
    <child link="roller_2_1_3"/>
  </joint>
  <link name="roller_2_1_4">
    <visual>
      <geometry>
        <box size="0.001 0.001 0.001"/>
      </geometry>
    </visual>
    <collision>
      <origin rpy="0 0 0" xyz="0 0 0"/>
      <geometry>
        <sphere radius="0.2"/>
      </geometry>
    </collision>
    <inertial>
      <origin rpy="0 1.57079632679 0" xyz="0 0 0"/>
      <mass value="0.00644011414341"/>
      <inertia ixx="4.31122707807e-05" ixy="0" ixz="0" iyy="4.31122707807e-05" iyz="0" izz="2.84524242856e-05"/>
    </inertial>
  </link>
  <joint name="roller_2_1_4_joint" type="continuous">
    <origin rpy="0 -5.65486677646 0" xyz="-0.125309937936        -0.09521        -0.172474333031"/>
    <parent link="wheel_2"/>
    <child link="roller_2_1_4"/>
  </joint>
</robot>
